<?xml version="1.0" encoding="utf-8"?>
<!-- =================================================================================== -->
<!-- |    This document was autogenerated by xacro from robot.xacro                    | -->
<!-- |    EDITING THIS FILE BY HAND IS NOT RECOMMENDED                                 | -->
<!-- =================================================================================== -->
<robot name="uwrt_mars_rover_sim">
  <gazebo>
    <!-- <plugin filename="libgazebo_ros_control.so" name="gazebo_ros_control">
    <robotNamespace>/</robotNamespace>
  </plugin> -->
    <plugin filename="libgazebo_uwrt_arm_hw.so" name="uwrt_arm_hw">
      <robotNamespace>/</robotNamespace>
    </plugin>
  </gazebo>
  <!-- Add additional plugins for main robot here -->
  <!-- TODO: Add wrist transmission here -->
  <!-- Add plugins for chassis control or sensors on chassis here -->
  <!-- Get the control_mode from the passed argument. -->
  <!-- <xacro:property name="_mode" value="$(arg mode)"/> -->
  <!-- TODO: add transmissions (maybe separate file) to actively controlled joints-->
  <!-- TODO: reconfigure the collisions into simple shapes for reduced CPU load -->
  <!-- TODO: add the counter weight for the chassis / rocker bogey (may need to recalculate inertia / split into two components)-->
  <link name="world"/>
  <joint name="base_link_joint" type="revolute">
    <parent link="world"/>
    <child link="base_link"/>
    <origin rpy="0 0 0" xyz="-0.037262 0.0004 0.05814"/>
    <axis rpy="0 0 0" xyz="0 0 1"/>
    <limit effort="0.001" lower="-0.001" upper="0.001" velocity="0.001"/>
  </joint>
  <link name="base_link">
    <inertial>
      <origin rpy="0 0 0" xyz="-0.037262 0.0004 0.05814"/>
      <mass value="16.69"/>
      <inertia ixx="1.19749" ixy="0.005489" ixz="0.017255" iyy="1.901358" iyz="0.01166538" izz="1.15907"/>
    </inertial>
    <visual>
      <origin rpy="0 0 0" xyz="0 0 0"/>
      <geometry>
        <mesh filename="/home/akeaveny/git/uwrt_arm_rl/gym-uwrt-arm/urdfs/uwrt_arm/new_urdf/meshes/chassis.stl" scale="0.001 0.001 0.001"/>
      </geometry>
      <material name="Silver">
          <color rgba="0.41176 0.41176 0.41176 1"/>
      </material>
    </visual>
    <collision>
      <origin rpy="0 0 0" xyz="0 0 0"/>
      <geometry>
        <mesh filename="/home/akeaveny/git/uwrt_arm_rl/gym-uwrt-arm/urdfs/uwrt_arm/new_urdf/meshes/chassis.stl" scale="0.001 0.001 0.001"/>
      </geometry>
    </collision>
  </link>
  <gazebo reference="base_link">
    <material>Gazebo/Black</material>
    <static>false</static>
    <gravity>true</gravity>
    <selfCollide>false</selfCollide>
  </gazebo>
  <link name="turntable">
    <inertial>
      <origin rpy="0 0 0" xyz="-0.00358 0.03422 0.05666"/>
      <mass value="1.26885"/>
      <inertia ixx="0.00397" ixy="-0.00035" ixz="0.00084" iyy="0.01033" iyz="-0.00008" izz="0.01305"/>
    </inertial>
    <visual>
      <origin rpy="0 0 0" xyz="0 0 0"/>
      <geometry>
        <mesh filename="/home/akeaveny/git/uwrt_arm_rl/gym-uwrt-arm/urdfs/uwrt_arm/new_urdf/meshes/turntable.stl" scale="0.0254 0.0254 0.0254"/>
      </geometry>
      <material name="Green">
        <color rgba="0 1 0 1"/>
      </material>
    </visual>
    <collision>
      <origin rpy="0 0 0" xyz="0 0 0"/>
      <geometry>
        <mesh filename="/home/akeaveny/git/uwrt_arm_rl/gym-uwrt-arm/urdfs/uwrt_arm/new_urdf/meshes/collisions/turntable.dae" scale="0.0254 0.0254 0.0254"/>
      </geometry>
    </collision>
  </link>
  <gazebo reference="turntable">
    <material>Gazebo/Green</material>
    <static>false</static>
    <gravity>true</gravity>
    <selfCollide>false</selfCollide>
  </gazebo>
  <joint name="turntable_to_chassis" type="revolute">
    <origin rpy="0.0 0.0 0.0" xyz="0.2445 0 -0.0222"/>
    <parent link="base_link"/>
    <child link="turntable"/>
    <axis xyz="0.0 0.0 1.0"/>
    <limit effort="10000" lower="-1.74532925199" upper="1.74532925199" velocity="0.5"/>
  </joint>
  <transmission name="turntable_trans">
    <type>transmission_interface/SimpleTransmission</type>
    <joint name="turntable_to_chassis">
      <!-- <hardwareInterface>hardware_interface/EffortJointInterface</hardwareInterface> -->
      <hardwareInterface>hardware_interface/PositionJointInterface</hardwareInterface>
      <hardwareInterface>hardware_interface/VelocityJointInterface</hardwareInterface>
    </joint>
    <actuator name="turntable_actuator">
      <mechanicalReduction>1</mechanicalReduction>
    </actuator>
  </transmission>
  <link name="bicep">
    <inertial>
      <origin rpy="0 0 0" xyz="0.21949 0.01582 0.12944"/>
      <mass value="6.480"/>
      <inertia ixx="0.049355726" ixy="-0.009202176" ixz="-0.033305137" iyy="0.185953394" iyz="-0.000337776" izz="0.156889351"/>
    </inertial>
    <visual>
      <origin rpy="0 0 0" xyz="0 0 -0.0381"/>
      <geometry>
        <mesh filename="/home/akeaveny/git/uwrt_arm_rl/gym-uwrt-arm/urdfs/uwrt_arm/new_urdf/meshes/bicep.stl" scale="0.0254 0.0254 0.0254"/>
      </geometry>
      <material name="Green">
        <color rgba="0 1 0 1"/>
      </material>
    </visual>
    <collision>
      <origin rpy="0 0 0" xyz="0 0 -0.0381"/>
      <geometry>
        <mesh filename="/home/akeaveny/git/uwrt_arm_rl/gym-uwrt-arm/urdfs/uwrt_arm/new_urdf/meshes/collisions/bicep.dae" scale="0.0254 0.0254 0.0254"/>
      </geometry>
    </collision>
  </link>
  <gazebo reference="bicep">
    <material>Gazebo/Green</material>
    <static>false</static>
    <gravity>true</gravity>
    <selfCollide>false</selfCollide>
  </gazebo>
  <joint name="shoulder" type="revolute">
    <origin rpy="0.0 0.0 0.0" xyz="0.015875 0 0.0544576"/>
    <parent link="turntable"/>
    <child link="bicep"/>
    <axis xyz="0.0 -1.0 0.0"/>
    <limit effort="10000" lower="-0.0872664625997" upper="0.872664625997" velocity="0.5"/>
  </joint>
  <transmission name="bicep_trans">
    <type>transmission_interface/SimpleTransmission</type>
    <joint name="shoulder">
      <!-- <hardwareInterface>hardware_interface/EffortJointInterface</hardwareInterface> -->
      <hardwareInterface>hardware_interface/PositionJointInterface</hardwareInterface>
      <hardwareInterface>hardware_interface/VelocityJointInterface</hardwareInterface>
    </joint>
    <actuator name="bicep_actuator">
      <mechanicalReduction>1</mechanicalReduction>
    </actuator>
  </transmission>
  <link name="forearm">
    <inertial>
      <origin rpy="0 0 0" xyz="0.273874 0.000309 -0.003062"/>
      <mass value="1.00758"/>
      <inertia ixx="0.002383071" ixy="0.0000089677" ixz="-0.000286743" iyy="0.010400499" iyz="-0.000000279" izz="0.012282219"/>
    </inertial>
    <visual>
      <origin rpy="0 0 0" xyz="0.318874 -0.151281 -0.062292"/>
      <geometry>
        <mesh filename="/home/akeaveny/git/uwrt_arm_rl/gym-uwrt-arm/urdfs/uwrt_arm/new_urdf/meshes/forearm.stl" scale="0.0254 0.0254 0.0254"/>
      </geometry>
      <material name="Green">
        <color rgba="0 1 0 1"/>
      </material>
    </visual>
    <collision>
      <origin rpy="0 0 0" xyz="0.318874 -0.151281 -0.062292"/>
      <geometry>
        <mesh filename="/home/akeaveny/git/uwrt_arm_rl/gym-uwrt-arm/urdfs/uwrt_arm/new_urdf/meshes/collisions/forearm.dae" scale="0.0254 0.0254 0.0254"/>
      </geometry>
    </collision>
  </link>
  <gazebo reference="forearm">
    <material>Gazebo/Green</material>
    <static>false</static>
    <gravity>true</gravity>
    <selfCollide>false</selfCollide>
  </gazebo>
  <joint name="elbow" type="revolute">
    <origin rpy="0.0 0.0 0.0" xyz="0.4019042 -0.0011938 0.0596138"/>
    <parent link="bicep"/>
    <child link="forearm"/>
    <axis xyz="0.0 -1.0 0.0"/>
    <limit effort="10000" lower="0.0" upper="1.0471975512" velocity="0.5"/>
  </joint>
  <transmission name="forearm_trans">
    <type>transmission_interface/SimpleTransmission</type>
    <joint name="elbow">
      <!-- <hardwareInterface>hardware_interface/EffortJointInterface</hardwareInterface> -->
      <hardwareInterface>hardware_interface/PositionJointInterface</hardwareInterface>
      <hardwareInterface>hardware_interface/VelocityJointInterface</hardwareInterface>
    </joint>
    <actuator name="forearm_actuator">
      <mechanicalReduction>1</mechanicalReduction>
    </actuator>
  </transmission>
  <link name="claw_up_down">
    <inertial>
      <origin rpy="0 0 0" xyz="-0.0133 0 0"/>
      <mass value="0.21436"/>
      <inertia ixx="0.000111209" ixy="0" ixz="-0.000032753" iyy="0.0001526999" iyz="0" izz="0.000138406"/>
    </inertial>
    <visual>
      <origin rpy="0 0 0" xyz="0 0 0"/>
      <geometry>
        <mesh filename="/home/akeaveny/git/uwrt_arm_rl/gym-uwrt-arm/urdfs/uwrt_arm/new_urdf/meshes/claw_up_down.stl" scale="0.0254 0.0254 0.0254"/>
      </geometry>
      <material name="Blue">
        <color rgba="0 0 1 1"/>
      </material>
    </visual>
  </link>
  <gazebo reference="claw_up_down">
    <material>Gazebo/Blue</material>
    <static>false</static>
    <gravity>true</gravity>
    <selfCollide>false</selfCollide>
  </gazebo>
  <joint name="wrist_up_down" type="revolute">
    <origin rpy="0.0 0.0 0.0" xyz="0.355638 0.000418 0"/>
    <parent link="forearm"/>
    <child link="claw_up_down"/>
    <axis xyz="0.0 1.0 0.0"/>
    <limit effort="10000" lower="-1.308996939" upper="1.308996939" velocity="0.5"/>
  </joint>
  <transmission name="claw_up_down_trans">
    <type>transmission_interface/SimpleTransmission</type>
    <joint name="wrist_up_down">
      <!-- <hardwareInterface>hardware_interface/EffortJointInterface</hardwareInterface> -->
      <hardwareInterface>hardware_interface/PositionJointInterface</hardwareInterface>
      <hardwareInterface>hardware_interface/VelocityJointInterface</hardwareInterface>
    </joint>
    <actuator name="claw_up_down_actuator">
      <mechanicalReduction>1</mechanicalReduction>
    </actuator>
  </transmission>
  <link name="claw_rotate">
    <inertial>
      <origin rpy="0 0 0" xyz="0.0186 0 0"/>
      <mass value="0.08276"/>
      <inertia ixx="0.0000195" ixy="0.000000055" ixz="-0.000023176" iyy="0.000056806" iyz="-0.00000152" izz="0.000043396"/>
    </inertial>
    <visual>
      <origin rpy="0 0 0" xyz="0 0 0"/>
      <geometry>
        <mesh filename="/home/akeaveny/git/uwrt_arm_rl/gym-uwrt-arm/urdfs/uwrt_arm/new_urdf/meshes/claw_rotate.stl" scale="0.0254 0.0254 0.0254"/>
      </geometry>
      <material name="Blue">
        <color rgba="0 0 1 1"/>
      </material>
    </visual>
  </link>
  <gazebo reference="claw_rotate">
    <material>Gazebo/Blue</material>
    <static>false</static>
    <gravity>true</gravity>
    <selfCollide>false</selfCollide>
  </gazebo>
  <joint name="wrist_rotate" type="continuous">
    <origin rpy="0.0 0.0 0.0" xyz="0 0 0"/>
    <parent link="claw_up_down"/>
    <child link="claw_rotate"/>
    <axis xyz="1.0 0.0 0.0"/>
  </joint>
  <transmission name="claw_rotate_trans">
    <type>transmission_interface/SimpleTransmission</type>
    <joint name="wrist_rotate">
      <!-- <hardwareInterface>hardware_interface/EffortJointInterface</hardwareInterface> -->
      <hardwareInterface>hardware_interface/PositionJointInterface</hardwareInterface>
      <hardwareInterface>hardware_interface/VelocityJointInterface</hardwareInterface>
    </joint>
    <actuator name="claw_rotate_actuator">
      <mechanicalReduction>1</mechanicalReduction>
    </actuator>
  </transmission>
  <link name="claw_static">
    <inertial>
      <origin rpy="0 0 0" xyz="0.03529 -0.00121 0.02018"/>
      <mass value="0.57339"/>
      <inertia ixx="0.0004705087" ixy="-0.0000169291" ixz="-0.0000989304" iyy="0.000579985" iyz="-0.000000533" izz="0.000651862"/>
    </inertial>
    <visual>
      <origin rpy="0 0 0" xyz="0.058 0 0"/>
      <geometry>
        <mesh filename="/home/akeaveny/git/uwrt_arm_rl/gym-uwrt-arm/urdfs/uwrt_arm/new_urdf/meshes/claw_static.stl" scale="0.0254 0.0254 0.0254"/>
      </geometry>
      <material name="Blue">
        <color rgba="0 0 1 1"/>
      </material>
    </visual>
  </link>
  <gazebo reference="claw_static">
    <material>Gazebo/Blue</material>
    <static>false</static>
    <gravity>true</gravity>
    <selfCollide>false</selfCollide>
  </gazebo>
  <joint name="wrist_static" type="fixed">
    <origin rpy="0.0 0.0 0.0" xyz="0.0652 0 0"/>
    <parent link="claw_rotate"/>
    <child link="claw_static"/>
  </joint>
  <link name="servo">
    <inertial>
      <origin rpy="0 0 0" xyz="0.0634 -0.00027 -0.02243"/>
      <mass value="0.0535"/>
      <inertia ixx="0.000009626" ixy="0.00000095" ixz="-0.0000095" iyy="0.0000714" iyz="-0.0000003" izz="0.00007375"/>
    </inertial>
    <visual>
      <origin rpy="0 0 0" xyz="-0.021 0 -0.029"/>
      <geometry>
        <mesh filename="/home/akeaveny/git/uwrt_arm_rl/gym-uwrt-arm/urdfs/uwrt_arm/new_urdf/meshes/servo.stl" scale="0.0254 0.0254 0.0254"/>
      </geometry>
      <material name="Blue">
        <color rgba="0 0 1 1"/>
      </material>
    </visual>
    <collision>
      <origin rpy="0 0 0" xyz="-0.021 0 -0.029"/>
      <geometry>
        <mesh filename="/home/akeaveny/git/uwrt_arm_rl/gym-uwrt-arm/urdfs/uwrt_arm/new_urdf/meshes/servo.stl" scale="0.0254 0.0254 0.0254"/>
      </geometry>
    </collision>
  </link>
  <gazebo reference="servo">
    <material>Gazebo/Blue</material>
    <static>false</static>
    <gravity>true</gravity>
    <selfCollide>false</selfCollide>
  </gazebo>
  <joint name="servo_joint" type="revolute">
    <origin rpy="0.0 0.0 0.0" xyz="0.079 0 0.029"/>
    <parent link="claw_static"/>
    <child link="servo"/>
    <axis xyz="0.0 1.0 0.0"/>
    <limit effort="10000" lower="-1e-8" upper="1e-8" velocity="0.5"/>
  </joint>
  <transmission name="servo_trans">
    <type>transmission_interface/SimpleTransmission</type>
    <joint name="servo_joint">
      <!-- <hardwareInterface>hardware_interface/EffortJointInterface</hardwareInterface> -->
      <hardwareInterface>hardware_interface/PositionJointInterface</hardwareInterface>
      <hardwareInterface>hardware_interface/VelocityJointInterface</hardwareInterface>
    </joint>
    <actuator name="servo_actuator">
      <mechanicalReduction>1</mechanicalReduction>
    </actuator>
  </transmission>
  <link name="hex_key">
    <inertial>
      <origin rpy="0 0 0" xyz="-0.033 0 -0.001"/>
      <mass value="0.0224"/>
      <inertia ixx="0.0000002" ixy="0" ixz="0.0000005" iyy="0.0000117" iyz="0" izz="0.0000117"/>
    </inertial>
    <visual>
      <origin rpy="0 0 0" xyz="-0.138 0 -0.005"/>
      <geometry>
        <mesh filename="/home/akeaveny/git/uwrt_arm_rl/gym-uwrt-arm/urdfs/uwrt_arm/new_urdf/meshes/hex_key.stl" scale="0.0254 0.0254 0.0254"/>
      </geometry>
      <material name="Blue">
        <color rgba="0 0 1 1"/>
      </material>
    </visual>
    <collision>
      <origin rpy="0 0 0" xyz="-0.138 0 -0.005"/>
      <geometry>
        <mesh filename="/home/akeaveny/git/uwrt_arm_rl/gym-uwrt-arm/urdfs/uwrt_arm/new_urdf/meshes/hex_key.stl" scale="0.0254 0.0254 0.0254"/>
      </geometry>
    </collision>
  </link>
  <gazebo reference="hex_key">
    <material>Gazebo/Blue</material>
    <static>false</static>
    <gravity>true</gravity>
    <selfCollide>false</selfCollide>
  </gazebo>
  <joint name="hex_joint" type="revolute">
    <origin rpy="0.0 0.0 0.0" xyz="0.118 0 -0.024"/>
    <parent link="servo"/>
    <child link="hex_key"/>
    <limit effort="10000" lower="-1e-8" upper="1e-8" velocity="0.5"/>
  </joint>
  <link name="gripper_finger_right">
    <inertial>
      <origin rpy="0 0 0" xyz="-0.02271 0.07079 0.02018"/>
      <mass value="0.0479"/>
      <inertia ixx="0.0000153325" ixy="-0.000015029" ixz="0" iyy="0.000060103" iyz="-0.000000144" izz="0.000071409"/>
    </inertial>
    <visual>
      <origin rpy="0 0 0" xyz="0 0.072 0"/>
      <geometry>
        <mesh filename="/home/akeaveny/git/uwrt_arm_rl/gym-uwrt-arm/urdfs/uwrt_arm/new_urdf/meshes/gripper_finger_right.stl" scale="0.0254 0.0254 0.0254"/>
      </geometry>
      <material name="Blue">
        <color rgba="0 0 1 1"/>
      </material>
    </visual>
    <collision>
      <origin rpy="0 0 0" xyz="0 0.072 0"/>
      <geometry>
        <mesh filename="/home/akeaveny/git/uwrt_arm_rl/gym-uwrt-arm/urdfs/uwrt_arm/new_urdf/meshes/gripper_finger_right.stl" scale="0.0254 0.0254 0.0254"/>
      </geometry>
    </collision>
  </link>
  <gazebo reference="gripper_finger_right">
    <material>Gazebo/Blue</material>
    <static>false</static>
    <gravity>true</gravity>
    <selfCollide>false</selfCollide>
  </gazebo>
  <joint name="gripper_joint_right" type="revolute">
    <origin rpy="0.0 0.0 0.0" xyz="0.058 -0.072 0"/>
    <parent link="claw_static"/>
    <child link="gripper_finger_right"/>
    <axis xyz="0.0 0.0 1.0"/>
    <!-- <limit effort="10000" lower="0.785398163396" upper="0.785398163397" velocity="0.5"/> -->
    <limit effort="10000" lower="-1e-8" upper="1e-8" velocity="0.5"/>
  </joint>
  <transmission name="gripper_finger_right_trans">
    <type>transmission_interface/SimpleTransmission</type>
    <joint name="gripper_joint_right">
      <!-- <hardwareInterface>hardware_interface/EffortJointInterface</hardwareInterface> -->
      <hardwareInterface>hardware_interface/PositionJointInterface</hardwareInterface>
      <hardwareInterface>hardware_interface/VelocityJointInterface</hardwareInterface>
    </joint>
    <actuator name="gripper_finger_right_actuator">
      <mechanicalReduction>1</mechanicalReduction>
    </actuator>
  </transmission>
  <link name="gripper_finger_left">
    <inertial>
      <origin rpy="0 0 0" xyz="-0.02271 -0.07321 0.02018"/>
      <mass value="0.0479"/>
      <inertia ixx="0.0000153325" ixy="-0.000015029" ixz="0" iyy="0.000060103" iyz="-0.000000144" izz="0.000071409"/>
    </inertial>
    <visual>
      <origin rpy="0 0 0" xyz="0 -0.072 0"/>
      <geometry>
        <mesh filename="/home/akeaveny/git/uwrt_arm_rl/gym-uwrt-arm/urdfs/uwrt_arm/new_urdf/meshes/gripper_finger_left.stl" scale="0.0254 0.0254 0.0254"/>
      </geometry>
      <material name="Blue">
        <color rgba="0 0 1 1"/>
      </material>
    </visual>
    <collision>
      <origin rpy="0 0 0" xyz="0 -0.072 0"/>
      <geometry>
        <mesh filename="/home/akeaveny/git/uwrt_arm_rl/gym-uwrt-arm/urdfs/uwrt_arm/new_urdf/meshes/gripper_finger_left.stl" scale="0.0254 0.0254 0.0254"/>
      </geometry>
    </collision>
  </link>
  <gazebo reference="gripper_finger_left">
    <material>Gazebo/Blue</material>
    <static>false</static>
    <gravity>true</gravity>
    <selfCollide>false</selfCollide>
  </gazebo>
  <joint name="gripper_joint_left" type="revolute">
    <origin rpy="0.0 0.0 0.0" xyz="0.058 0.072 0"/>
    <parent link="claw_static"/>
    <child link="gripper_finger_left"/>
    <axis xyz="0.0 0.0 1.0"/>
    <!-- <limit effort="10000" lower="0.785398163396" upper="0.785398163397" velocity="0.5"/> -->
    <limit effort="10000" lower="-1e-8" upper="1e-8" velocity="0.5"/>
  </joint>
  <transmission name="gripper_finger_left_trans">
    <type>transmission_interface/SimpleTransmission</type>
    <joint name="gripper_joint_left">
      <!-- <hardwareInterface>hardware_interface/EffortJointInterface</hardwareInterface> -->
      <hardwareInterface>hardware_interface/PositionJointInterface</hardwareInterface>
      <hardwareInterface>hardware_interface/VelocityJointInterface</hardwareInterface>
    </joint>
    <actuator name="gripper_finger_left_actuator">
      <mechanicalReduction>1</mechanicalReduction>
    </actuator>
  </transmission>
  <!-- <xacro:if value="${_mode == 'arm_mission' or _mode == 'arm_only'}">
  <xacro:arm_to_base base_object="base_link"/>
</xacro:if> -->
  <!-- Add the science module to the chassis of the robot. -->
  <!-- <xacro:if value="${_mode == 'science_mission' or _mode == 'science_only'}"> -->
  <!-- TODO: Add the science macro here. -->
  <!-- </xacro:if> -->
  <!-- TODO: update COM of the rocker components -->
  <link name="rocker_left">
    <inertial>
      <origin rpy="0 0 0" xyz="0.0003 0.02583 0.07381"/>
      <mass value="4.84"/>
      <inertia ixx="0.073122" ixy="-0.0001" ixz="0.00015" iyy="0.187572" iyz="0.02183" izz="0.15447"/>
    </inertial>
    <visual>
      <origin rpy="0 0 0.0" xyz="0 0.0254 0"/>
      <geometry>
        <mesh filename="/home/akeaveny/git/uwrt_arm_rl/gym-uwrt-arm/urdfs/uwrt_arm/new_urdf/meshes/rocker.stl" scale="0.0254 0.0254 0.0254"/>
      </geometry>
      <material name="Red">
        <color rgba="1 0 0 1"/>
      </material>
    </visual>
    <collision>
      <origin rpy="0 0 0.0" xyz="0 0.0254 0"/>
      <geometry>
        <mesh filename="/home/akeaveny/git/uwrt_arm_rl/gym-uwrt-arm/urdfs/uwrt_arm/new_urdf/meshes/rocker.stl" scale="0.0254 0.0254 0.0254"/>
      </geometry>
    </collision>
  </link>
  <gazebo reference="rocker_left">
    <material>Gazebo/Red</material>
    <static>false</static>
    <gravity>true</gravity>
    <selfCollide>false</selfCollide>
  </gazebo>
  <!-- TODO: Make this a revolute rocker joint and write the differential bar transmission -->
  <joint name="rocker_left_to_chassis" type="revolute">
    <origin rpy="0.0 0.0 0.0" xyz="0 0.24289 0"/>
    <parent link="base_link"/>
    <child link="rocker_left"/>
    <!-- <axis xyz="0.0 1.0 0.0"/> -->
    <limit effort="10000" lower="-1e-8" upper="1e-8" velocity="0.5"/>
  </joint>
  <link name="wheel_left_front">
    <inertial>
      <origin rpy="0 0 0" xyz="0 0.09398 0"/>
      <mass value="1.32"/>
      <inertia ixx="0.0137" ixy="0" ixz="0" iyy="0.0191595" iyz="0" izz="0.0137"/>
    </inertial>
    <visual>
      <origin rpy="0 0 0" xyz="0 0.09398 0"/>
      <geometry>
        <mesh filename="/home/akeaveny/git/uwrt_arm_rl/gym-uwrt-arm/urdfs/uwrt_arm/new_urdf/meshes/wheel.stl" scale="0.0254 0.0254 0.0254"/>
      </geometry>
        <material name="Black">
          <color rgba="0 0 0 1"/>
        </material>
    </visual>
    <collision>
      <origin rpy="0 0 0" xyz="0 0.09398 0"/>
      <geometry>
        <mesh filename="/home/akeaveny/git/uwrt_arm_rl/gym-uwrt-arm/urdfs/uwrt_arm/new_urdf/meshes/wheel.stl" scale="0.0254 0.0254 0.0254"/>
      </geometry>
    </collision>
  </link>
  <joint name="wheel_left_front_to_rocker" type="continuous">
    <origin rpy="0.0 0.0 0.0" xyz="0.381 0.07414 -0.15636"/>
    <parent link="rocker_left"/>
    <child link="wheel_left_front"/>
    <axis xyz="0.0 1.0 0.0"/>
  </joint>
  <!-- TODO: Fix these physics parameters to make them accurate -->
  <gazebo reference="wheel_left_front">
    <material>Gazebo/Red</material>
    <mu1>1</mu1>
    <mu2>1</mu2>
    <fdir1>1 0 0</fdir1>
    <minDepth>0.001</minDepth>
    <maxVel>3.0</maxVel>
    <gravity>true</gravity>
    <kp value="10000000.0"/>
    <kd value="1.0"/>
    <selfCollide>false</selfCollide>
  </gazebo>
  <transmission name="wheel_left_front_trans">
    <type>transmission_interface/SimpleTransmission</type>
    <joint name="wheel_left_front_to_rocker">
      <hardwareInterface>hardware_interface/VelocityJointInterface</hardwareInterface>
    </joint>
    <actuator name="wheel_left_front_actuator">
      <mechanicalReduction>43.8311688312</mechanicalReduction>
    </actuator>
  </transmission>
  <link name="wheel_left_back">
    <inertial>
      <origin rpy="0 0 0" xyz="0 0.09398 0"/>
      <mass value="1.32"/>
      <inertia ixx="0.0137" ixy="0" ixz="0" iyy="0.0191595" iyz="0" izz="0.0137"/>
    </inertial>
    <visual>
      <origin rpy="0 0 0" xyz="0 0.09398 0"/>
      <geometry>
        <mesh filename="/home/akeaveny/git/uwrt_arm_rl/gym-uwrt-arm/urdfs/uwrt_arm/new_urdf/meshes/wheel.stl" scale="0.0254 0.0254 0.0254"/>
      </geometry>
      <material name="Black"/>
    </visual>
    <collision>
      <origin rpy="0 0 0" xyz="0 0.09398 0"/>
      <geometry>
        <mesh filename="/home/akeaveny/git/uwrt_arm_rl/gym-uwrt-arm/urdfs/uwrt_arm/new_urdf/meshes/wheel.stl" scale="0.0254 0.0254 0.0254"/>
      </geometry>
    </collision>
  </link>
  <joint name="wheel_left_back_to_rocker" type="continuous">
    <origin rpy="0.0 0.0 0.0" xyz="-0.381 0.07414 -0.15636"/>
    <parent link="rocker_left"/>
    <child link="wheel_left_back"/>
    <axis xyz="0.0 1.0 0.0"/>
  </joint>
  <!-- TODO: Fix these physics parameters to make them accurate -->
  <gazebo reference="wheel_left_back">
    <material>Gazebo/Black</material>
    <mu1>1</mu1>
    <mu2>1</mu2>
    <fdir1>1 0 0</fdir1>
    <minDepth>0.001</minDepth>
    <maxVel>3.0</maxVel>
    <gravity>true</gravity>
    <kp value="10000000.0"/>
    <kd value="1.0"/>
    <selfCollide>false</selfCollide>
  </gazebo>
  <transmission name="wheel_left_back_trans">
    <type>transmission_interface/SimpleTransmission</type>
    <joint name="wheel_left_back_to_rocker">
      <hardwareInterface>hardware_interface/VelocityJointInterface</hardwareInterface>
    </joint>
    <actuator name="wheel_left_back_actuator">
      <mechanicalReduction>43.8311688312</mechanicalReduction>
    </actuator>
  </transmission>
  <!-- TODO: update COM of the rocker components -->
  <link name="rocker_right">
    <inertial>
      <origin rpy="0 0 0" xyz="0.0003 0.02583 0.07381"/>
      <mass value="4.84"/>
      <inertia ixx="0.073122" ixy="-0.0001" ixz="0.00015" iyy="0.187572" iyz="0.02183" izz="0.15447"/>
    </inertial>
    <visual>
      <origin rpy="0 0 3.14159265359" xyz="0 -0.0254 0"/>
      <geometry>
        <mesh filename="/home/akeaveny/git/uwrt_arm_rl/gym-uwrt-arm/urdfs/uwrt_arm/new_urdf/meshes/rocker.stl" scale="0.0254 0.0254 0.0254"/>
      </geometry>
      <material name="Red">
        <color rgba="1 0 0 1"/>
      </material>
    </visual>
    <collision>
      <origin rpy="0 0 3.14159265359" xyz="0 -0.0254 0"/>
      <geometry>
        <mesh filename="/home/akeaveny/git/uwrt_arm_rl/gym-uwrt-arm/urdfs/uwrt_arm/new_urdf/meshes/rocker.stl" scale="0.0254 0.0254 0.0254"/>
      </geometry>
    </collision>
  </link>
  <gazebo reference="rocker_right">
    <material>Gazebo/Red</material>
    <static>false</static>
    <gravity>true</gravity>
    <selfCollide>false</selfCollide>
  </gazebo>
  <!-- TODO: Make this a revolute rocker joint and write the differential bar transmission -->
  <joint name="rocker_right_to_chassis" type="revolute">
    <origin rpy="0.0 0.0 0.0" xyz="0 -0.24289 0"/>
    <parent link="base_link"/>
    <child link="rocker_right"/>
    <!-- <axis xyz="0.0 1.0 0.0"/> -->
    <limit effort="10000" lower="-1e-8" upper="1e-8" velocity="0.5"/>
  </joint>
  <link name="wheel_right_back">
    <inertial>
      <origin rpy="0 0 0" xyz="0 -0.09398 0"/>
      <mass value="1.32"/>
      <inertia ixx="0.0137" ixy="0" ixz="0" iyy="0.0191595" iyz="0" izz="0.0137"/>
    </inertial>
    <visual>
      <origin rpy="0 0 0" xyz="0 -0.09398 0"/>
      <geometry>
        <mesh filename="/home/akeaveny/git/uwrt_arm_rl/gym-uwrt-arm/urdfs/uwrt_arm/new_urdf/meshes/wheel.stl" scale="0.0254 0.0254 0.0254"/>
      </geometry>
      <material name="Black">
          <color rgba="0 0 0 1"/>
      </material>
    </visual>
    <collision>
      <origin rpy="0 0 0" xyz="0 -0.09398 0"/>
      <geometry>
        <mesh filename="/home/akeaveny/git/uwrt_arm_rl/gym-uwrt-arm/urdfs/uwrt_arm/new_urdf/meshes/wheel.stl" scale="0.0254 0.0254 0.0254"/>
      </geometry>
    </collision>
  </link>
  <joint name="wheel_right_back_to_rocker" type="continuous">
    <origin rpy="0.0 0.0 0.0" xyz="-0.381 -0.07414 -0.15636"/>
    <parent link="rocker_right"/>
    <child link="wheel_right_back"/>
    <axis xyz="0.0 1.0 0.0"/>
  </joint>
  <!-- TODO: Fix these physics parameters to make them accurate -->
  <gazebo reference="wheel_right_back">
    <material>Gazebo/Black</material>
    <mu1>1</mu1>
    <mu2>1</mu2>
    <fdir1>1 0 0</fdir1>
    <minDepth>0.001</minDepth>
    <maxVel>3.0</maxVel>
    <gravity>true</gravity>
    <kp value="10000000.0"/>
    <kd value="1.0"/>
    <selfCollide>false</selfCollide>
  </gazebo>
  <transmission name="wheel_right_back_trans">
    <type>transmission_interface/SimpleTransmission</type>
    <joint name="wheel_right_back_to_rocker">
      <hardwareInterface>hardware_interface/VelocityJointInterface</hardwareInterface>
    </joint>
    <actuator name="wheel_right_back_actuator">
      <mechanicalReduction>43.8311688312</mechanicalReduction>
    </actuator>
  </transmission>
  <link name="wheel_right_front">
    <inertial>
      <origin rpy="0 0 0" xyz="0 -0.09398 0"/>
      <mass value="1.32"/>
      <inertia ixx="0.0137" ixy="0" ixz="0" iyy="0.0191595" iyz="0" izz="0.0137"/>
    </inertial>
    <visual>
      <origin rpy="0 0 0" xyz="0 -0.09398 0"/>
      <geometry>
        <mesh filename="/home/akeaveny/git/uwrt_arm_rl/gym-uwrt-arm/urdfs/uwrt_arm/new_urdf/meshes/wheel.stl" scale="0.0254 0.0254 0.0254"/>
      </geometry>
      <material name="Black">
        <color rgba="0 0 0 1"/>
      </material>
    </visual>
    <collision>
      <origin rpy="0 0 0" xyz="0 -0.09398 0"/>
      <geometry>
        <mesh filename="/home/akeaveny/git/uwrt_arm_rl/gym-uwrt-arm/urdfs/uwrt_arm/new_urdf/meshes/wheel.stl" scale="0.0254 0.0254 0.0254"/>
      </geometry>
    </collision>
  </link>
  <joint name="wheel_right_front_to_rocker" type="continuous">
    <origin rpy="0.0 0.0 0.0" xyz="0.381 -0.07414 -0.15636"/>
    <parent link="rocker_right"/>
    <child link="wheel_right_front"/>
    <axis xyz="0.0 1.0 0.0"/>
  </joint>
  <!-- TODO: Fix these physics parameters to make them accurate -->
  <gazebo reference="wheel_right_front">
    <material>Gazebo/Black</material>
    <mu1>1</mu1>
    <mu2>1</mu2>
    <fdir1>1 0 0</fdir1>
    <minDepth>0.001</minDepth>
    <maxVel>3.0</maxVel>
    <gravity>true</gravity>
    <kp value="10000000.0"/>
    <kd value="1.0"/>
    <selfCollide>false</selfCollide>
  </gazebo>
  <transmission name="wheel_right_front_trans">
    <type>transmission_interface/SimpleTransmission</type>
    <joint name="wheel_right_front_to_rocker">
      <hardwareInterface>hardware_interface/VelocityJointInterface</hardwareInterface>
    </joint>
    <actuator name="wheel_right_front_actuator">
      <mechanicalReduction>43.8311688312</mechanicalReduction>
    </actuator>
  </transmission>
</robot>

